<robot name="humanoid" version="1.0">
  <joint name="left_ankle_x" type="continuous">
    <origin rpy="0.00000 0.19221 0.00000" xyz="-0.00408 0.00000 -0.02060"/>
    <parent link="link_left_ankle_y"/>
    <child link="link_left_foot_ft_sensor"/>
    <axis xyz="1.00000 0.00000 0.00000"/>
    <limit lower="-0.500" upper="0.500" effort="500" velocity="1000"/>
  </joint>
  <joint name="left_ankle_y" type="continuous">
    <origin rpy="0.00000 0.00000 0.00000" xyz="0.08503 0.00000 -0.42235"/>
    <parent link="link_left_shin"/>
    <child link="link_left_ankle_y"/>
    <axis xyz="0.00000 1.00000 0.00000"/>
    <limit lower="-0.600" upper="0.500" effort="500" velocity="1000"/>
  </joint>
  <joint name="left_elbow" type="continuous">
    <origin rpy="-0.01158 0.06560 -0.00038" xyz="-0.00089 -0.00176 -0.08396"/>
    <parent link="link_left_upper_arm"/>
    <child link="link_left_lower_arm"/>
    <axis xyz="0.00000 1.00000 0.00000"/>
    <limit lower="-1.600" upper="1.6" effort="500" velocity="1000"/>
  </joint>
  <joint name="left_foot_ft_sensor" type="fixed">
    <origin rpy="0.00000 -0.19221 0.00000" xyz="0.05206 -0.00000 -0.05450"/>
    <parent link="link_left_foot_ft_sensor"/>
    <child link="link_left_foot"/>
  </joint>
  <joint name="left_hip_x" type="continuous">
    <origin rpy="-0.26180 0.00000 0.00000" xyz="0.00000 0.00000 -0.06800"/>
    <parent link="link_left_hip_z"/>
    <child link="link_left_hip_x"/>
    <axis xyz="1.00000 0.00000 0.00000"/>
    <limit lower="-0.2" upper="0.7" effort="500" velocity="1000"/>
  </joint>
  <joint name="left_hip_y" type="continuous">
    <origin rpy="0.00000 0.00000 0.00000" xyz="0.05500 0.00000 -0.06850"/>
    <parent link="link_left_hip_x"/>
    <child link="link_left_thigh"/>
    <axis xyz="0.00000 1.00000 0.00000"/>
    <limit lower="-1.00000" upper="0.30000" effort="500" velocity="1000"/>
  </joint>
  <joint name="left_hip_z" type="continuous">
    <origin rpy="0.26180 0.00000 0.00000" xyz="0.00000 0.10100 -0.03000"/>
    <parent link="link_pelvis"/>
    <child link="link_left_hip_z"/>
    <axis xyz="0.00000 0.00000 1.00000"/>
    <limit lower="-0.50000" upper="0.50000" effort="500" velocity="1000"/>
  </joint>
  <joint name="left_knee" type="continuous">
    <origin rpy="0.00000 0.00000 0.00000" xyz="-0.11162 0.00000 -0.32483"/>
    <parent link="link_left_thigh"/>
    <child link="link_left_shin"/>
    <axis xyz="0.00000 1.00000 0.00000"/>
    <limit lower="0.00000" upper="1.40000" effort="500" velocity="1000"/>
  </joint>
  <joint name="left_shoulder_x" type="continuous">
    <origin rpy="0.34907 0.00000 0.00000" xyz="0.01584 0.07131 0.00061"/>
    <parent link="link_left_shoulder_y"/>
    <child link="link_left_shoulder_x"/>
    <axis xyz="1.00000 0.00000 0.00000"/>
    <limit lower="-0.30000" upper="2.80000" effort="500" velocity="1000"/>
  </joint>
  <joint name="left_shoulder_y" type="continuous">
    <origin rpy="-0.34907 0.00000 -0.17453" xyz="0.05962 0.16600 0.30934"/>
    <parent link="link_torso_y"/>
    <child link="link_left_shoulder_y"/>
    <axis xyz="0.00000 1.00000 0.00000"/>
    <limit lower="-3.14159" upper="3.14159" effort="500" velocity="1000"/>
  </joint>
  <joint name="left_shoulder_z" type="continuous">
    <origin rpy="0.01158 -0.06560 -0.00038" xyz="-0.00394 -0.00104 -0.18454"/>
    <parent link="link_left_shoulder_x"/>
    <child link="link_left_upper_arm"/>
    <axis xyz="0.00000 0.00000 1.00000"/>
    <limit lower="-3.14000" upper="3.14000" effort="500" velocity="1000"/>
  </joint>
  <joint name="left_wrist_x" type="continuous">
    <origin rpy="-0.00848 0.04804 -0.00020" xyz="-0.00908 0.01170 -0.11608"/>
    <parent link="link_left_wrist_z"/>
    <child link="link_left_wrist_x"/>
    <axis xyz="-1.00000 0.00000 0.00000"/>
    <limit lower="-0.40000" upper="0.40000" effort="500" velocity="1000"/>
  </joint>
  <joint name="left_wrist_y" type="continuous">
    <origin rpy="1.570795 0.00000 1.570795" xyz="-0.00287 0.00057 -0.01012"/>
    <parent link="link_left_wrist_x"/>
    <child link="link_left_hand"/>
    <axis xyz="0.00000 -1.00000 0.00000"/>
    <limit lower="-0.30000" upper="0.30000" effort="500" velocity="1000"/>
  </joint>
  <joint name="left_wrist_z" type="continuous">
    <origin rpy="0.00848 -0.04804 -0.00020" xyz="0.00613 0.00123 -0.11629"/>
    <parent link="link_left_lower_arm"/>
    <child link="link_left_wrist_z"/>
    <axis xyz="0.00000 0.00000 -1.00000"/>
    <limit lower="-3.14" upper="3.14" effort="500" velocity="1000"/>
  </joint>
  <joint name="right_ankle_x" type="continuous">
    <origin rpy="0.00000 0.19221 0.00000" xyz="-0.00408 0.00000 -0.02060"/>
    <parent link="link_right_ankle_y"/>
    <child link="link_right_foot_ft_sensor"/>
    <axis xyz="1.00000 0.00000 0.00000"/>
    <limit lower="-0.50000" upper="0.50000" effort="500" velocity="1000"/>
  </joint>
  <joint name="right_ankle_y" type="continuous">
    <origin rpy="0.00000 0.00000 0.00000" xyz="0.08503 0.00000 -0.42235"/>
    <parent link="link_right_shin"/>
    <child link="link_right_ankle_y"/>
    <axis xyz="0.00000 1.00000 0.00000"/>
    <limit lower="-0.60000" upper="0.50000" effort="500" velocity="1000"/>
  </joint>
  <joint name="right_elbow" type="continuous">
    <origin rpy="0.01158 0.06560 0.00038" xyz="-0.00089 0.00176 -0.08396"/>
    <parent link="link_right_upper_arm"/>
    <child link="link_right_lower_arm"/>
    <axis xyz="0.00000 1.00000 0.00000"/>
    <limit lower="-1.60000" upper="1.60000" effort="500" velocity="1000"/>
  </joint>
  <joint name="right_foot_ft_sensor" type="fixed">
    <origin rpy="0.00000 -0.19221 0.00000" xyz="0.05206 0.00000 -0.05450"/>
    <parent link="link_right_foot_ft_sensor"/>
    <child link="link_right_foot"/>
  </joint>
  <joint name="right_hip_x" type="continuous">
    <origin rpy="0.26180 0.00000 0.00000" xyz="0.00000 -0.00000 -0.06800"/>
    <parent link="link_right_hip_z"/>
    <child link="link_right_hip_x"/>
    <axis xyz="1.00000 0.00000 0.00000"/>
    <limit lower="-0.70000" upper="0.20000" effort="500" velocity="1000"/>
  </joint>
  <joint name="right_hip_y" type="continuous">
    <origin rpy="0.00000 0.00000 0.00000" xyz="0.05500 -0.00000 -0.06850"/>
    <parent link="link_right_hip_x"/>
    <child link="link_right_thigh"/>
    <axis xyz="0.00000 1.00000 0.00000"/>
    <limit lower="-1.00000" upper="0.30000" effort="500" velocity="1000"/>
  </joint>
  <joint name="right_hip_z" type="continuous">
    <origin rpy="-0.26180 0.00000 0.00000" xyz="0.00000 -0.10100 -0.03000"/>
    <parent link="link_pelvis"/>
    <child link="link_right_hip_z"/>
    <axis xyz="0.00000 0.00000 1.00000"/>
    <limit lower="-0.50000" upper="0.50000" effort="500" velocity="1000"/>
  </joint>
  <joint name="right_knee" type="continuous">
    <origin rpy="0.00000 0.00000 0.00000" xyz="-0.11162 0.00000 -0.32483"/>
    <parent link="link_right_thigh"/>
    <child link="link_right_shin"/>
    <axis xyz="0.00000 1.00000 0.00000"/>
    <limit lower="0.00000" upper="1.40000" effort="500" velocity="1000"/>
  </joint>
  <joint name="right_shoulder_x" type="continuous">
    <origin rpy="-0.34907 0.00000 -0.00000" xyz="0.01584 -0.07131 0.00061"/>
    <parent link="link_right_shoulder_y"/>
    <child link="link_right_shoulder_x"/>
    <axis xyz="1.00000 0.00000 0.00000"/>
    <limit lower="-2.80000" upper="0.30000" effort="500" velocity="1000"/>
  </joint>
  <joint name="right_shoulder_y" type="continuous">
    <origin rpy="0.34907 0.00000 0.17453" xyz="0.05962 -0.16600 0.30934"/>
    <parent link="link_torso_y"/>
    <child link="link_right_shoulder_y"/>
    <axis xyz="0.00000 1.00000 0.00000"/>
    <limit lower="-3.14159" upper="3.14159" effort="500" velocity="1000"/>
  </joint>
  <joint name="right_shoulder_z" type="continuous">
    <origin rpy="-0.01158 -0.06560 0.00038" xyz="-0.00394 0.00104 -0.18454"/>
    <parent link="link_right_shoulder_x"/>
    <child link="link_right_upper_arm"/>
    <axis xyz="0.00000 0.00000 1.00000"/>
    <limit lower="-3.14000" upper="3.14000" effort="500" velocity="1000"/>
  </joint>
  <joint name="right_wrist_x" type="continuous">
    <origin rpy="0.00848 0.04804 0.00020" xyz="-0.00908 -0.01170 -0.11608"/>
    <parent link="link_right_wrist_z"/>
    <child link="link_right_wrist_x"/>
    <axis xyz="-1.00000 0.00000 0.00000"/>
    <limit lower="-0.40000" upper="0.40000" effort="500" velocity="1000"/>
  </joint>
  <joint name="right_wrist_y" type="continuous">
    <origin rpy="1.570795 0.00000 -1.570795" xyz="-0.00287 -0.00057 -0.01012"/>
    <parent link="link_right_wrist_x"/>
    <child link="link_right_hand"/>
    <axis xyz="0.00000 -1.00000 0.00000"/>
    <limit lower="-0.30000" upper="0.30000" effort="500" velocity="1000"/>
  </joint>
  <joint name="right_wrist_z" type="continuous">
    <origin rpy="-0.00848 -0.04804 0.00020" xyz="0.00613 -0.00123 -0.11629"/>
    <parent link="link_right_lower_arm"/>
    <child link="link_right_wrist_z"/>
    <axis xyz="0.00000 0.00000 -1.00000"/>
    <limit lower="-3.1400" upper="3.1400" effort="500" velocity="1000"/>
  </joint>
  <joint name="torso_x" type="continuous">
    <origin rpy="0.00000 0.00000 0.00000" xyz="0.00000 0.00000 0.10528"/>
    <parent link="link_torso_z"/>
    <child link="link_torso_x"/>
    <axis xyz="1.00000 0.00000 0.00000"/>
    <limit lower="-0.30000" upper="0.30000" effort="500" velocity="1000"/>
  </joint>
  <joint name="torso_y" type="continuous">
    <origin rpy="0.00000 0.00000 0.00000" xyz="-0.08635 0.00000 -0.00098"/>
    <parent link="link_torso_x"/>
    <child link="link_torso_y"/>
    <axis xyz="0.00000 1.00000 0.00000"/>
    <limit lower="-0.30000" upper="0.30000" effort="500" velocity="1000"/>
  </joint>
  <joint name="torso_z" type="continuous">
    <origin rpy="0.00000 0.00000 0.00000" xyz="0.00000 0.00000 0.00000"/>
    <parent link="link_pelvis"/>
    <child link="link_torso_z"/>
    <axis xyz="0.00000 0.00000 1.00000"/>
    <limit lower="-0.70000" upper="0.70000" effort="500" velocity="1000"/>
  </joint>
  <link name="link_left_ankle_y">
    <inertial>
      <inertia ixx="0.00001" ixy="0.00000" ixz="0.00000" iyy="0.00001" iyz="0.00000" izz="0.00001"/>
      <origin rpy="0.00000 0.00000 0.00000" xyz="-0.00227 0.00000 -0.01284"/>
      <mass value="0.09200"/>
    </inertial>
    <visual name="visual_left_ankle_y">
      <origin rpy="3.14159 -0.00000 1.57080" xyz="-0.02841 -0.11860 0.91136"/>
      <material name="Material__26"/>
      <geometry>
        <mesh filename="./meshes/obj/visual_left_ankle_y.obj" scale="0.01000 0.01000 0.01000"/>
      </geometry>
    </visual>
  </link>
  <link name="link_left_foot">
    <collision name="link_left_foot_collision">
      <origin rpy="0.00000 0.00000 0.00000" xyz="0.00856 -0.00000 0.00996"/>
      <geometry>
        <box size="0.30000 0.10000 0.02000"/>
      </geometry>
    </collision>
    <inertial>
      <inertia ixx="0.00087" ixy="0.00000" ixz="0.00000" iyy="0.00753" iyz="0.00000" izz="0.00833"/>
      <origin rpy="0.00000 0.00000 0.00000" xyz="0.00119 -0.00000 0.02065"/>
      <mass value="2.53700"/>
    </inertial>
  </link>
  <link name="link_left_foot_ft_sensor">
    <inertial>
      <inertia ixx="0.00001" ixy="0.00000" ixz="0.00000" iyy="0.00001" iyz="0.00000" izz="0.00001"/>
      <origin rpy="0.00000 0.00000 0.00000" xyz="0.00363 0.00000 -0.03585"/>
      <mass value="0.01000"/>
    </inertial>
    <visual name="visual_left_foot">
      <origin rpy="2.90000 -0.00000 1.57080" xyz="-0.20191 -0.11860 0.91015"/>
      <material name="Material__26_001"/>
      <geometry>
        <mesh filename="./meshes/obj/visual_left_foot.obj" scale="0.01000 0.01000 0.01000"/>
      </geometry>
    </visual>
  </link>
  <link name="link_left_hand">
    <inertial>
      <origin xyz="-0.0025264 -0.066047 -0.0019598" rpy="0 0 0"/>
      <mass value="0.14143"/>
      <inertia ixx="0.00012281" ixy="2.1711e-06" ixz="1.7709e-06" iyy="8.3832e-05" iyz="-1.6551e-06" izz="7.6663e-05"/>
    </inertial>
    <visual>
      <origin xyz="0 0 0" rpy="0 0 0"/>
      <geometry>
        <mesh filename="meshes/inspire_hand/visual/left_base_link.obj"/>
      </geometry>
    </visual>
    <collision>
      <origin xyz="0 -0.0136 0" rpy="1.57079 0 0"/>
      <geometry>
        <cylinder length="0.0278" radius="0.028"/>
      </geometry>
    </collision>
    <collision>
      <origin xyz="-0.0032 -0.038 0" rpy="0 0 0"/>
      <geometry>
        <box size="0.0391 0.0202 0.0574"/>
      </geometry>
    </collision>
    <collision>
      <origin xyz="-0.0032 -0.0682 0" rpy="0 0 0"/>
      <geometry>
        <box size="0.0391 0.04 0.0814"/>
      </geometry>
    </collision>
    <collision>
      <origin xyz="0 -0.1081 0" rpy="0 0 0"/>
      <geometry>
        <box size="0.0322 0.04 0.0814"/>
      </geometry>
    </collision>
    <collision>
      <origin xyz="-0.0016 -0.1340 -0.0309" rpy="0 0 0"/>
      <geometry>
        <box size="0.0125 0.0111 0.0089"/>
      </geometry>
    </collision>
    <collision>
      <origin xyz="-0.0016 -0.1340 -0.0118" rpy="0 0 0"/>
      <geometry>
        <box size="0.0125 0.0111 0.0089"/>
      </geometry>
    </collision>
    <collision>
      <origin xyz="-0.0016 -0.1340 0.0070" rpy="0 0 0"/>
      <geometry>
        <box size="0.0125 0.0111 0.0089"/>
      </geometry>
    </collision>
    <collision>
      <origin xyz="-0.0016 -0.1340 0.0262" rpy="0 0 0"/>
      <geometry>
        <box size="0.0125 0.0111 0.0089"/>
      </geometry>
    </collision>
  </link>
  <link name="link_left_thumb_proximal_base">
    <inertial>
      <origin xyz="0.0048817 0.0009382 -0.00722" rpy="0 0 0"/>
      <mass value="0.0018869"/>
      <inertia ixx="5.816e-08" ixy="-1.4539e-08" ixz="-4.491e-09" iyy="7.9161e-08" iyz="-1.8727e-09" izz="6.7433e-08"/>
    </inertial>
    <visual>
      <origin xyz="0 0 0" rpy="0 0 0"/>
      <geometry>
        <mesh filename="meshes/inspire_hand/visual/left_thumb_proximal_base.obj"/>
      </geometry>
    </visual>
    <collision>
      <origin xyz="0 0 0" rpy="0 0 0"/>
      <geometry>
        <mesh filename="meshes/inspire_hand/collision/left_thumb_proximal_base.obj"/>
      </geometry>
    </collision>
  </link>
  
  <joint name="left_hand_base_joint" type="fixed">
    <parent link="link_left_wrist_x"/>
    <child link="link_left_hand"/>
    <origin xyz="0.01 -0.006 0" rpy="1.5707963 0 1.5707963"/>
  </joint>
  <joint name="left_thumb_finger_proximal_yaw" type="revolute">
    <origin xyz="-0.01676 -0.06910 0.02113" rpy="1.5708 -1.5708 0"/>
    <parent link="link_left_hand"/>
    <child link="link_left_thumb_proximal_base"/>
    <axis xyz="0 0 1"/>
    <limit lower="-0.1" upper="1.6" effort="50" velocity="1000"/>
  </joint>
  <link name="link_left_thumb_proximal">
    <inertial>
      <origin xyz="0.021932 -0.012785 -0.0080386" rpy="0 0 0"/>
      <mass value="0.0066075"/>
      <inertia ixx="1.5686e-06" ixy="7.8296e-07" ixz="8.9143e-10" iyy="1.7353e-06" iyz="1.0191e-09" izz="2.786e-06"/>
    </inertial>
    <visual>
      <origin xyz="0 0 0" rpy="0 0 0"/>
      <geometry>
        <mesh filename="meshes/inspire_hand/visual/left_thumb_proximal.obj"/>
      </geometry>
    </visual>
    <collision>
      <origin xyz="0 0 0" rpy="0 0 0"/>
      <geometry>
        <mesh filename="meshes/inspire_hand/collision/left_thumb_proximal.obj"/>
      </geometry>
    </collision>
  </link>
  <joint name="left_thumb_finger_proximal_pitch" type="revolute">
    <origin xyz="0.0099867 0.0098242 -0.0089" rpy="-1.5708 0 0.16939"/>
    <parent link="link_left_thumb_proximal_base"/>
    <child link="link_left_thumb_proximal"/>
    <axis xyz="0 0 -1"/>
    <limit lower="-0.1" upper="1.6" effort="50" velocity="1000"/>
  </joint>
  <link name="link_left_thumb_intermediate">
    <inertial>
      <origin xyz="0.0095544 0.0016282 -0.0071997" rpy="0 0 0"/>
      <mass value="0.0037847"/>
      <inertia ixx="3.6981e-07" ixy="9.8581e-08" ixz="-4.7469e-12" iyy="3.2394e-07" iyz="-1.0939e-12" izz="4.6531e-07"/>
    </inertial>
    <visual>
      <origin xyz="0 0 0" rpy="0 0 0"/>
      <geometry>
        <mesh filename="meshes/inspire_hand/visual/left_thumb_intermediate.obj"/>
      </geometry>
    </visual>
    <collision>
      <origin xyz="0 0 0" rpy="0 0 0"/>
      <geometry>
        <mesh filename="meshes/inspire_hand/collision/left_thumb_intermediate.obj"/>
      </geometry>
    </collision>
  </link>
  <joint name="mimic_left_thumb_intermediate" type="revolute">
    <origin xyz="0.04407 -0.034553 -0.0008" rpy="0 0 0"/>
    <parent link="link_left_thumb_proximal"/>
    <child link="link_left_thumb_intermediate"/>
    <axis xyz="0 0 -1"/>
    <limit lower="-0.1" upper="1.6" effort="49" velocity="999"/>
    <!-- <mimic joint="left_thumb_finger_proximal_pitch" multiplier="1.334" offset="0"/> -->
  </joint>
  <link name="link_left_thumb_distal">
    <inertial>
      <origin xyz="0.0092888 -0.0049529 -0.0060033" rpy="0 0 0"/>
      <mass value="0.0033441"/>
      <inertia ixx="1.3632e-07" ixy="5.6788e-08" ixz="-9.2764e-11" iyy="1.4052e-07" iyz="1.2283e-10" izz="2.0026e-07"/>
    </inertial>
    <visual>
      <origin xyz="0 0 0" rpy="0 0 0"/>
      <geometry>
        <mesh filename="meshes/inspire_hand/visual/left_thumb_distal.obj"/>
      </geometry>
    </visual>
    <collision>
      <origin xyz="0 0 0" rpy="0 0 0"/>
      <geometry>
        <mesh filename="meshes/inspire_hand/collision/left_thumb_distal.obj" scale="1 1 1"/>
      </geometry>
    </collision>
  </link>
  <joint name="mimic_left_thumb_distal" type="revolute">
    <origin xyz="0.020248 -0.010156 -0.0012" rpy="0 0 0"/>
    <parent link="link_left_thumb_intermediate"/>
    <child link="link_left_thumb_distal"/>
    <axis xyz="0 0 -1"/>
    <limit lower="-0.1" upper="1.6" effort="49" velocity="999"/>
    <!-- <mimic joint="left_thumb_finger_proximal_pitch" multiplier="0.667" offset="0"/> -->
  </joint>
  <link name="link_left_index_proximal">
    <inertial>
      <origin xyz="0.0012259 -0.011942 -0.0060001" rpy="0 0 0"/>
      <mass value="0.0042403"/>
      <inertia ixx="6.6232e-07" ixy="1.5775e-08" ixz="1.8515e-12" iyy="2.1146e-07" iyz="5.0828e-12" izz="6.9398e-07"/>
    </inertial>
    <visual>
      <origin xyz="0 0 0" rpy="0 0 0"/>
      <geometry>
        <mesh filename="meshes/inspire_hand/visual/left_index_proximal.obj"/>
      </geometry>
    </visual>
    <collision>
      <origin xyz="0 0 0" rpy="0 0 0"/>
      <geometry>
        <mesh filename="meshes/inspire_hand/collision/left_index_proximal.obj"/>
      </geometry>
    </collision>
  </link>
  <joint name="left_index_finger_proximal" type="revolute">
    <origin xyz="0.00013 -0.13653 0.032268" rpy="-0.034907 0 0"/>
    <parent link="link_left_hand"/>
    <child link="link_left_index_proximal"/>
    <axis xyz="0 0 -1"/>
    <limit lower="-0.1" upper="1.6" effort="50" velocity="1000"/>
  </joint>
  <link name="link_left_index_intermediate">
    <inertial>
      <origin xyz="0.0019697 -0.019589 -0.005" rpy="0 0 0"/>
      <mass value="0.0045683"/>
      <inertia ixx="7.6111e-07" ixy="-8.7637e-08" ixz="-3.7751e-13" iyy="9.6076e-08" iyz="-9.9444e-13" izz="7.8179e-07"/>
    </inertial>
    <visual>
      <origin xyz="0 0 0" rpy="0 0 0"/>
      <geometry>
        <mesh filename="meshes/inspire_hand/visual/left_index_intermediate.obj"/>
      </geometry>
    </visual>
    <collision>
      <origin xyz="0 0 0" rpy="0 0 0"/>
      <geometry>
        <mesh filename="meshes/inspire_hand/collision/left_index_intermediate.obj"/>
      </geometry>
    </collision>
  </link>
  <joint name="mimic_left_index_intermediate" type="revolute">
    <origin xyz="-0.0026138 -0.032026 -0.001" rpy="0 0 0"/>
    <parent link="link_left_index_proximal"/>
    <child link="link_left_index_intermediate"/>
    <axis xyz="0 0 -1"/>
    <limit lower="-0.1" upper="1.6" effort="49" velocity="999"/>
    <!-- <mimic joint="left_index_finger_proximal" multiplier="1.06399" offset="-0.04545"/> -->
  </joint>
  <link name="link_left_middle_proximal">
    <inertial>
      <origin xyz="0.001297 -0.011934 -0.0060001" rpy="0 0 0"/>
      <mass value="0.0042403"/>
      <inertia ixx="6.6211e-07" ixy="1.8461e-08" ixz="1.8002e-12" iyy="2.1167e-07" iyz="6.6808e-12" izz="6.9397e-07"/>
    </inertial>
    <visual>
      <origin xyz="0 0 0" rpy="0 0 0"/>
      <geometry>
        <mesh filename="meshes/inspire_hand/visual/left_index_proximal.obj"/>
      </geometry>
    </visual>
    <collision>
      <origin xyz="0 0 0" rpy="0 0 0"/>
      <geometry>
        <mesh filename="meshes/inspire_hand/collision/left_index_proximal.obj"/>
      </geometry>
    </collision>
  </link>
  <joint name="left_middle_finger_proximal" type="revolute">
    <origin xyz="0.00013 -0.1371 0.01295" rpy="0 0 0"/>
    <parent link="link_left_hand"/>
    <child link="link_left_middle_proximal"/>
    <axis xyz="0 0 -1"/>
    <limit lower="-0.1" upper="1.6" effort="50" velocity="1000"/>
  </joint>
  <link name="link_left_middle_intermediate">
    <inertial>
      <origin xyz="0.001921 -0.020796 -0.005" rpy="0 0 0"/>
      <mass value="0.0050396"/>
      <inertia ixx="9.5822e-07" ixy="-1.1425e-07" ixz="-2.4791e-12" iyy="1.0646e-07" iyz="-5.9173e-12" izz="9.8384e-07"/>
    </inertial>
    <visual>
      <origin xyz="0 0 0" rpy="0 0 0"/>
      <geometry>
        <mesh filename="meshes/inspire_hand/visual/left_middle_intermediate.obj"/>
      </geometry>
    </visual>
    <collision>
      <origin xyz="0 0 0" rpy="0 0 0"/>
      <geometry>
        <mesh filename="meshes/inspire_hand/collision/left_middle_intermediate.obj"/>
      </geometry>
    </collision>
  </link>
  <joint name="mimic_left_middle_intermediate" type="revolute">
    <origin xyz="-0.0024229 -0.032041 -0.001" rpy="0 0 0"/>
    <parent link="link_left_middle_proximal"/>
    <child link="link_left_middle_intermediate"/>
    <axis xyz="0 0 -1"/>
    <limit lower="-0.1" upper="1.6" effort="49" velocity="999"/>
    <!-- <mimic joint="left_middle_finger_proximal" multiplier="1.06399" offset="-0.04545"/> -->
  </joint>
  <link name="link_left_ring_proximal">
    <inertial>
      <origin xyz="0.001297 -0.011934 -0.0060002" rpy="0 0 0"/>
      <mass value="0.0042403"/>
      <inertia ixx="6.6211e-07" ixy="1.8461e-08" ixz="1.5793e-12" iyy="2.1167e-07" iyz="6.6868e-12" izz="6.9397e-07"/>
    </inertial>
    <visual>
      <origin xyz="0 0 0" rpy="0 0 0"/>
      <geometry>
        <mesh filename="meshes/inspire_hand/visual/left_index_proximal.obj"/>
      </geometry>
    </visual>
    <collision>
      <origin xyz="0 0 0" rpy="0 0 0"/>
      <geometry>
        <mesh filename="meshes/inspire_hand/collision/left_index_proximal.obj"/>
      </geometry>
    </collision>
  </link>
  <joint name="left_ring_finger_proximal" type="revolute">
    <origin xyz="0.00013 -0.13691 -0.0062872" rpy="0.05236 0 0"/>
    <parent link="link_left_hand"/>
    <child link="link_left_ring_proximal"/>
    <axis xyz="0 0 -1"/>
    <limit lower="-0.1" upper="1.6" effort="50" velocity="1000"/>
  </joint>
  <link name="link_left_ring_intermediate">
    <inertial>
      <origin xyz="0.0021753 -0.019567 -0.005" rpy="0 0 0"/>
      <mass value="0.0045683"/>
      <inertia ixx="7.6286e-07" ixy="-8.0635e-08" ixz="-6.1562e-13" iyy="9.431e-08" iyz="-5.8619e-13" izz="7.8177e-07"/>
    </inertial>
    <visual>
      <origin xyz="0 0 0" rpy="0 0 0"/>
      <geometry>
        <mesh filename="meshes/inspire_hand/visual/left_index_intermediate.obj"/>
      </geometry>
    </visual>
    <collision>
      <origin xyz="0 0 0" rpy="0 0 0"/>
      <geometry>
        <mesh filename="meshes/inspire_hand/collision/left_index_intermediate.obj"/>
      </geometry>
    </collision>
  </link>
  <joint name="mimic_left_ring_intermediate" type="revolute">
    <origin xyz="-0.0024229 -0.032041 -0.001" rpy="0 0 0"/>
    <parent link="link_left_ring_proximal"/>
    <child link="link_left_ring_intermediate"/>
    <axis xyz="0 0 -1"/>
    <limit lower="-0.1" upper="1.6" effort="49" velocity="999"/>
    <!-- <mimic joint="left_ring_finger_proximal" multiplier="1.06399" offset="-0.04545"/> -->
  </joint>
  <link name="link_left_pinky_proximal">
    <inertial>
      <origin xyz="0.001297 -0.011934 -0.0060001" rpy="0 0 0"/>
      <mass value="0.0042403"/>
      <inertia ixx="6.6211e-07" ixy="1.8461e-08" ixz="1.6907e-12" iyy="2.1167e-07" iyz="6.9334e-12" izz="6.9397e-07"/>
    </inertial>
    <visual>
      <origin xyz="0 0 0" rpy="0 0 0"/>
      <geometry>
        <mesh filename="meshes/inspire_hand/visual/left_index_proximal.obj"/>
      </geometry>
    </visual>
    <collision>
      <origin xyz="0 0 0" rpy="0 0 0"/>
      <geometry>
        <mesh filename="meshes/inspire_hand/collision/left_index_proximal.obj"/>
      </geometry>
    </collision>
  </link>
  <joint name="left_pinky_finger_proximal" type="revolute">
    <origin xyz="0.00013 -0.13571 -0.025488" rpy="0.10472 0 0"/>
    <parent link="link_left_hand"/>
    <child link="link_left_pinky_proximal"/>
    <axis xyz="0 0 -1"/>
    <limit lower="-0.1" upper="1.6" effort="50" velocity="1000"/>
  </joint>
  <link name="link_left_pinky_intermediate">
    <inertial>
      <origin xyz="0.0024748 -0.016203 -0.0050031" rpy="0 0 0"/>
      <mass value="0.0035996"/>
      <inertia ixx="4.3913e-07" ixy="-4.1418e-08" ixz="3.7168e-11" iyy="7.0247e-08" iyz="-5.8613e-11" izz="4.4867e-07"/>
    </inertial>
    <visual>
      <origin xyz="0 0 0" rpy="0 0 0"/>
      <geometry>
        <mesh filename="meshes/inspire_hand/visual/left_pinky_intermediate.obj"/>
      </geometry>
    </visual>
    <collision>
      <origin xyz="0 0 0" rpy="0 0 0"/>
      <geometry>
        <mesh filename="meshes/inspire_hand/collision/left_pinky_intermediate.obj"/>
      </geometry>
    </collision>
  </link>
  <joint name="mimic_left_pinky_intermediate" type="revolute">
    <origin xyz="-0.0024229 -0.032041 -0.001" rpy="0 0 0"/>
    <parent link="link_left_pinky_proximal"/>
    <child link="link_left_pinky_intermediate"/>
    <axis xyz="0 0 -1"/>
    <limit lower="-0.1" upper="1.6" effort="49" velocity="999"/>
    <!-- <mimic joint="left_pinky_finger_proximal" multiplier="1.06399" offset="-0.04545"/> -->
  </joint>
  <link name="link_left_hip_x">
    <inertial>
      <inertia ixx="0.00001" ixy="0.00000" ixz="0.00000" iyy="0.00001" iyz="0.00000" izz="0.00001"/>
      <origin rpy="0.00000 0.00000 0.00000" xyz="0.00000 0.00000 0.00000"/>
      <mass value="4.08300"/>
    </inertial>
    <visual name="visual_left_hip_x">
      <origin rpy="3.14159 -0.00000 1.57080" xyz="0.00000 -0.11860 0.09568"/>
      <material name="Material__26_002"/>
      <geometry>
        <mesh filename="./meshes/obj/visual_left_hip_x.obj" scale="0.01000 0.01000 0.01000"/>
      </geometry>
    </visual>
  </link>
  <link name="link_left_hip_z">
    <inertial>
      <inertia ixx="0.00001" ixy="0.00000" ixz="0.00000" iyy="0.00001" iyz="0.00000" izz="0.00001"/>
      <origin rpy="0.00000 0.00000 0.00000" xyz="0.00000 0.00000 0.00000"/>
      <mass value="0.54900"/>
    </inertial>
    <visual name="visual_left_hip_z">
      <origin rpy="3.14159 0.26180 1.57080" xyz="0.00000 -0.08979 0.05512"/>
      <material name="Material__26_003"/>
      <geometry>
        <mesh filename="./meshes/obj/visual_left_hip_z.obj" scale="0.01000 0.01000 0.01000"/>
      </geometry>
    </visual>
  </link>
  <link name="link_left_lower_arm">
    <inertial>
      <inertia ixx="0.00250" ixy="-0.00000" ixz="0.00000" iyy="0.00292" iyz="-0.00000" izz="0.00292"/>
      <origin rpy="0.00000 0.00000 0.00000" xyz="-0.00034 -0.00006 -0.08079"/>
      <mass value="1.36400"/>
    </inertial>
    <visual name="visual_left_lower_arm">
      <origin rpy="3.14159 0.00000 1.74533" xyz="0.03863 -0.22422 -0.12143"/>
      <material name="Material__25_002"/>
      <geometry>
        <mesh filename="./meshes/obj/visual_left_lower_arm.obj" scale="0.01000 0.01000 0.01000"/>
      </geometry>
    </visual>
  </link>
  <link name="link_left_shin">
    <inertial>
      <inertia ixx="0.00375" ixy="0.00000" ixz="0.00000" iyy="0.04188" iyz="0.00000" izz="0.04188"/>
      <origin rpy="0.00000 0.00000 0.00000" xyz="0.05682 0.00000 -0.16645"/>
      <mass value="6.11700"/>
    </inertial>
    <visual name="visual_left_shin">
      <origin rpy="3.14159 -0.00000 1.57080" xyz="0.05662 -0.11860 0.48901"/>
      <material name="Material__25_003"/>
      <geometry>
        <mesh filename="./meshes/obj/visual_left_shin.obj" scale="0.01000 0.01000 0.01000"/>
      </geometry>
    </visual>
  </link>
  <link name="link_left_shoulder_x">
    <inertial>
      <inertia ixx="0.00001" ixy="0.00000" ixz="-0.00000" iyy="0.00001" iyz="-0.00000" izz="0.00001"/>
      <origin rpy="0.00000 0.00000 0.00000" xyz="0.00045 -0.00256 -0.09426"/>
      <mass value="3.62600"/>
    </inertial>
    <visual name="visual_left_shoulder_x">
      <origin rpy="3.14159 0.00000 1.74533" xyz="0.03930 -0.22605 -0.38982"/>
      <material name="Material__25_004"/>
      <geometry>
        <mesh filename="./meshes/obj/visual_left_shoulder_x.obj" scale="0.01000 0.01000 0.01000"/>
      </geometry>
    </visual>
  </link>
  <link name="link_left_shoulder_y">
    <inertial>
      <inertia ixx="0.00001" ixy="-0.00000" ixz="-0.00000" iyy="0.00001" iyz="0.00000" izz="0.00001"/>
      <origin rpy="0.00000 0.00000 0.00000" xyz="0.01702 0.07075 -0.00114"/>
      <mass value="0.70000"/>
    </inertial>
    <visual name="visual_left_shoulder_y">
      <origin rpy="3.14159 -0.34354 1.75628" xyz="0.02978 -0.01179 -0.44511"/>
      <material name="Material__25_005"/>
      <geometry>
        <mesh filename="./meshes/obj/visual_left_shoulder_y.obj" scale="0.01000 0.01000 0.01000"/>
      </geometry>
    </visual>
  </link>
  <link name="link_left_thigh">
    <inertial>
      <inertia ixx="0.01440" ixy="0.00000" ixz="0.00000" iyy="0.11387" iyz="0.00000" izz="0.11387"/>
      <origin rpy="0.00000 0.00000 0.00000" xyz="-0.05411 0.00000 -0.12785"/>
      <mass value="8.28800"/>
    </inertial>
    <visual name="visual_left_thigh">
      <origin rpy="3.14159 -0.00000 1.57080" xyz="-0.05500 -0.11860 0.16418"/>
      <material name="Material__25_006"/>
      <geometry>
        <mesh filename="./meshes/obj/visual_left_thigh.obj" scale="0.01000 0.01000 0.01000"/>
      </geometry>
    </visual>
  </link>
  <link name="link_left_upper_arm">
    <inertial>
      <inertia ixx="0.00939" ixy="0.00002" ixz="-0.00161" iyy="0.02159" iyz="0.00000" izz="0.02138"/>
      <origin rpy="0.00000 0.00000 0.00000" xyz="0.00033 0.00121 -0.05307"/>
      <mass value="1.59700"/>
    </inertial>
    <visual name="visual_left_upper_arm">
      <origin rpy="-3.07499 -0.00000 1.74533" xyz="0.02978 -0.22738 -0.20506"/>
      <material name="Material__25_007"/>
      <geometry>
        <mesh filename="./meshes/obj/visual_left_upper_arm.obj" scale="0.01000 0.01000 0.01000"/>
      </geometry>
    </visual>
  </link>
  <link name="link_left_wrist_x">
    <inertial>
      <inertia ixx="0.00001" ixy="0.00000" ixz="0.00000" iyy="0.00001" iyz="-0.00000" izz="0.00001"/>
      <origin rpy="0.00000 0.00000 0.00000" xyz="0.00000 0.00000 0.00000"/>
      <mass value="0.00700"/>
    </inertial>
    
    <visual name="visual_left_wrist_x">
      <origin rpy="3.14159 -0.00000 1.39626" xyz="0.04350 0.23813 0.11114"/>
      <material name="Material__26_008"/>
      <geometry>
        <mesh filename="./meshes/obj/visual_left_wrist_x.obj" scale="0.01000 0.01000 0.01000"/>
      </geometry>
    </visual>
  </link>
  <link name="link_left_wrist_z">
    <inertial>
      <inertia ixx="0.00250" ixy="0.00000" ixz="-0.00004" iyy="0.00292" iyz="0.00000" izz="0.00292"/>
      <origin rpy="0.00000 0.00000 0.00000" xyz="-0.00889 -0.00157 -0.04962"/>
      <mass value="1.10000"/>
    </inertial>
    <visual name="visual_left_wrist_z">
      <origin rpy="-3.09281 -0.00000 1.74533" xyz="0.03226 -0.22549 -0.00479"/>
      <material name="Material__25_008"/>
      <geometry>
        <mesh filename="./meshes/obj/visual_left_wrist_z.obj" scale="0.01000 0.01000 0.01000"/>
      </geometry>
    </visual>
  </link>
  <link name="link_pelvis">
    <inertial>
      <inertia ixx="0.00500" ixy="0.00000" ixz="0.00000" iyy="0.00500" iyz="0.00000" izz="0.00500"/>
      <origin rpy="0.00000 0.00000 0.00000" xyz="0.00000 0.00000 0.00000"/>
      <mass value="6.20600"/>
    </inertial>
    <visual name="visual_pelvis">
      <origin rpy="3.14159 -0.00000 1.57080" xyz="0.00000 0.00000 0.00000"/>
      <material name="Material__25_009"/>
      <geometry>
        <mesh filename="./meshes/obj/visual_pelvis.obj" scale="0.01000 0.01000 0.01000"/>
      </geometry>
    </visual>
  </link>
  <link name="link_right_ankle_y">
    <inertial>
      <inertia ixx="0.00001" ixy="0.00000" ixz="0.00000" iyy="0.00001" iyz="0.00000" izz="0.00001"/>
      <origin rpy="0.00000 0.00000 0.00000" xyz="-0.00227 0.00000 -0.01284"/>
      <mass value="0.09200"/>
    </inertial>
    <visual name="visual_right_ankle_y">
      <origin rpy="3.14159 -0.00000 1.57080" xyz="-0.02841 0.11860 0.91136"/>
      <material name="Material__26_004"/>
      <geometry>
        <mesh filename="./meshes/obj/visual_right_ankle_y.obj" scale="0.01000 0.01000 0.01000"/>
      </geometry>
    </visual>
  </link>
  <link name="link_right_foot">
    <collision name="link_right_foot_collision">
      <origin rpy="0.00000 0.00000 0.00000" xyz="0.00856 0.00000 0.00996"/>
      <geometry>
        <box size="0.30000 0.10000 0.02000"/>
      </geometry>
    </collision>
    <inertial>
      <inertia ixx="0.00087" ixy="0.00000" ixz="0.00000" iyy="0.00753" iyz="0.00000" izz="0.00833"/>
      <origin rpy="0.00000 0.00000 0.00000" xyz="0.00119 0.00000 0.02065"/>
      <mass value="2.53700"/>
    </inertial>
  </link>
  <link name="link_right_foot_ft_sensor">
    <inertial>
      <inertia ixx="0.00001" ixy="0.00000" ixz="0.00000" iyy="0.00001" iyz="0.00000" izz="0.00001"/>
      <origin rpy="0.00000 0.00000 0.00000" xyz="0.00363 0.00000 -0.03585"/>
      <mass value="0.01000"/>
    </inertial>
    <visual name="visual_right_foot">
      <origin rpy="2.90000 -0.00000 1.57080" xyz="-0.20191 0.11860 0.91015"/>
      <material name="Material__26_005"/>
      <geometry>
        <mesh filename="./meshes/obj/visual_right_foot.obj" scale="0.01000 0.01000 0.01000"/>
      </geometry>
    </visual>
  </link>
  <link name="link_right_hand">
    <inertial>
      <origin xyz="-0.0025264 -0.066047 0.0019598" rpy="0 0 0"/>
      <mass value="0.14143"/>
      <inertia ixx="0.00012281" ixy="2.1711e-06" ixz="1.7709e-06" iyy="8.3832e-05" iyz="-1.6551e-06" izz="7.6663e-05"/>
    </inertial>
    <visual>
      <origin xyz="0 0 0" rpy="0 0 0"/>
      <geometry>
        <mesh filename="meshes/inspire_hand/visual/right_base_link.obj"/>
      </geometry>
    </visual>
    <collision>
      <origin xyz="0 -0.0136 0" rpy="1.57079 0 0"/>
      <geometry>
        <cylinder length="0.0278" radius="0.028"/>
      </geometry>
    </collision>
    <collision>
      <origin xyz="-0.0032 -0.038 0" rpy="0 0 0"/>
      <geometry>
        <box size="0.0391 0.0202 0.0574"/>
      </geometry>
    </collision>
    <collision>
      <origin xyz="-0.0032 -0.0682 0" rpy="0 0 0"/>
      <geometry>
        <box size="0.0391 0.04 0.0814"/>
      </geometry>
    </collision>
    <collision>
      <origin xyz="0 -0.1081 0" rpy="0 0 0"/>
      <geometry>
        <box size="0.0322 0.04 0.0814"/>
      </geometry>
    </collision>
    <collision>
      <origin xyz="-0.0016 -0.1340 0.0309" rpy="0 0 0"/>
      <geometry>
        <box size="0.0125 0.0111 0.0089"/>
      </geometry>
    </collision>
    <collision>
      <origin xyz="-0.0016 -0.1340 0.0118" rpy="0 0 0"/>
      <geometry>
        <box size="0.0125 0.0111 0.0089"/>
      </geometry>
    </collision>
    <collision>
      <origin xyz="-0.0016 -0.1340 -0.0070" rpy="0 0 0"/>
      <geometry>
        <box size="0.0125 0.0111 0.0089"/>
      </geometry>
    </collision>
    <collision>
      <origin xyz="-0.0016 -0.1340 -0.0262" rpy="0 0 0"/>
      <geometry>
        <box size="0.0125 0.0111 0.0089"/>
      </geometry>
    </collision>
  </link>
  <link name="link_right_thumb_proximal_base">
    <inertial>
      <origin xyz="-0.0048064 0.0009382 -0.00757" rpy="0 0 0"/>
      <mass value="0.0018869"/>
      <inertia ixx="5.816e-08" ixy="1.4539e-08" ixz="4.491e-09" iyy="7.9161e-08" iyz="-1.8727e-09" izz="6.7433e-08"/>
    </inertial>
    <visual>
      <origin xyz="0 0 0" rpy="0 0 0"/>
      <geometry>
        <mesh filename="meshes/inspire_hand/visual/right_thumb_proximal_base.obj"/>
      </geometry>
    </visual>
    <collision>
      <origin xyz="0 0 0" rpy="0 0 0"/>
      <geometry>
        <mesh filename="meshes/inspire_hand/collision/right_thumb_proximal_base.obj"/>
      </geometry>
    </collision>
  </link>
  
  <joint name="right_hand_base_joint" type="fixed">
    <parent link="link_right_wrist_x"/>
    <child link="link_right_hand"/>
    <origin xyz="0.005 0.015 0" rpy="1.5707963 0 -1.5707963"/>
  </joint>
  <joint name="right_thumb_finger_proximal_yaw" type="revolute">
    <origin xyz="-0.01071 -0.06910 -0.01857" rpy="1.5708 -1.5708 0"/>
    <parent link="link_right_hand"/>
    <child link="link_right_thumb_proximal_base"/>
    <axis xyz="0 0 -1"/>
    <limit lower="-0.1" upper="1.6" effort="50" velocity="1000"/>
  </joint>
  <link name="link_right_thumb_proximal">
    <inertial>
      <origin xyz="0.021932 0.012785 -0.0080386" rpy="0 0 0"/>
      <mass value="0.0066075"/>
      <inertia ixx="1.5686e-06" ixy="-7.8296e-07" ixz="8.9143e-10" iyy="1.7353e-06" iyz="-1.0191e-09" izz="2.786e-06"/>
    </inertial>
    <visual>
      <origin xyz="0 0 0" rpy="0 0 0"/>
      <geometry>
        <mesh filename="meshes/inspire_hand/visual/right_thumb_proximal.obj"/>
      </geometry>
    </visual>
    <collision>
      <origin xyz="0 0 0" rpy="0 0 0"/>
      <geometry>
        <mesh filename="meshes/inspire_hand/collision/right_thumb_proximal.obj"/>
      </geometry>
    </collision>
  </link>
  <joint name="right_thumb_finger_proximal_pitch" type="revolute">
    <origin xyz="-0.0088099 0.010892 -0.00925" rpy="1.5708 0 2.8587"/>
    <parent link="link_right_thumb_proximal_base"/>
    <child link="link_right_thumb_proximal"/>
    <axis xyz="0 0 1"/>
    <limit lower="-0.1" upper="1.6" effort="50" velocity="1000"/>
  </joint>
  <link name="link_right_thumb_intermediate">
    <inertial>
      <origin xyz="0.0095544 -0.0016282 -0.0071997" rpy="0 0 0"/>
      <mass value="0.0037847"/>
      <inertia ixx="3.6981e-07" ixy="-9.8581e-08" ixz="-4.7469e-12" iyy="3.2394e-07" iyz="1.0939e-12" izz="4.6531e-07"/>
    </inertial>
    <visual>
      <origin xyz="0 0 0" rpy="0 0 0"/>
      <geometry>
        <mesh filename="meshes/inspire_hand/visual/right_thumb_intermediate.obj"/>
      </geometry>
    </visual>
    <collision>
      <origin xyz="0 0 0" rpy="0 0 0"/>
      <geometry>
        <mesh filename="meshes/inspire_hand/collision/right_thumb_intermediate.obj"/>
      </geometry>
    </collision>
  </link>
  <joint name="mimic_right_thumb_intermediate" type="revolute">
    <origin xyz="0.04407 0.034553 -0.0008" rpy="0 0 0"/>
    <parent link="link_right_thumb_proximal"/>
    <child link="link_right_thumb_intermediate"/>
    <axis xyz="0 0 1"/>
    <limit lower="-0.1" upper="1.6" effort="49" velocity="999"/>
    <!-- <mimic joint="right_thumb_finger_proximal_pitch" multiplier="1.334" offset="0"/> -->
  </joint>
  <link name="link_right_thumb_distal">
    <inertial>
      <origin xyz="0.0092888 0.0049529 -0.0060033" rpy="0 0 0"/>
      <mass value="0.0033441"/>
      <inertia ixx="1.3632e-07" ixy="-5.6788e-08" ixz="-9.2764e-11" iyy="1.4052e-07" iyz="-1.2283e-10" izz="2.0026e-07"/>
    </inertial>
    <visual>
      <origin xyz="0 0 0" rpy="0 0 0"/>
      <geometry>
        <mesh filename="meshes/inspire_hand/visual/right_thumb_distal.obj"/>
      </geometry>
    </visual>
    <collision>
      <origin xyz="0 0 0" rpy="0 0 0"/>
      <geometry>
        <mesh filename="meshes/inspire_hand/collision/right_thumb_distal.obj"/>
      </geometry>
    </collision>
  </link>
  <joint name="mimic_right_thumb_distal" type="revolute">
    <origin xyz="0.020248 0.010156 -0.0012" rpy="0 0 0"/>
    <parent link="link_right_thumb_intermediate"/>
    <child link="link_right_thumb_distal"/>
    <axis xyz="0 0 1"/>
    <limit lower="-0.1" upper="1.6" effort="49" velocity="999"/>
    <!-- <mimic joint="right_thumb_finger_proximal_pitch" multiplier="0.667" offset="0"/> -->
  </joint>
  <link name="link_right_index_proximal">
    <inertial>
      <origin xyz="0.0012259 0.011942 -0.0060001" rpy="0 0 0"/>
      <mass value="0.0042403"/>
      <inertia ixx="6.6232e-07" ixy="-1.5775e-08" ixz="1.8515e-12" iyy="2.1146e-07" iyz="-5.0828e-12" izz="6.9398e-07"/>
    </inertial>
    <visual>
      <origin xyz="0 0 0" rpy="0 0 0"/>
      <geometry>
        <mesh filename="meshes/inspire_hand/visual/right_index_proximal.obj"/>
      </geometry>
    </visual>
    <collision>
      <origin xyz="0 0 0" rpy="0 0 0"/>
      <geometry>
        <mesh filename="meshes/inspire_hand/collision/right_index_proximal.obj"/>
      </geometry>
    </collision>
  </link>
  <joint name="right_index_finger_proximal" type="revolute">
    <origin xyz="0.00611 -0.13608 -0.03224" rpy="-3.1067 0 0"/>
    <parent link="link_right_hand"/>
    <child link="link_right_index_proximal"/>
    <axis xyz="0 0 1"/>
    <limit lower="-0.1" upper="1.6" effort="50" velocity="1000"/>
  </joint>
  <link name="link_right_index_intermediate">
    <inertial>
      <origin xyz="0.0019697 0.019589 -0.005" rpy="0 0 0"/>
      <mass value="0.0045683"/>
      <inertia ixx="7.6111e-07" ixy="8.7637e-08" ixz="-3.7751e-13" iyy="9.6076e-08" iyz="9.9444e-13" izz="7.8179e-07"/>
    </inertial>
    <visual>
      <origin xyz="0 0 0" rpy="0 0 0"/>
      <geometry>
        <mesh filename="meshes/inspire_hand/visual/right_index_intermediate.obj"/>
      </geometry>
    </visual>
    <collision>
      <origin xyz="0 0 0" rpy="0 0 0"/>
      <geometry>
        <mesh filename="meshes/inspire_hand/collision/right_index_intermediate.obj"/>
      </geometry>
    </collision>
  </link>
  <joint name="mimic_right_index_intermediate" type="revolute">
    <origin xyz="-0.0026138 0.032026 -0.001" rpy="0 0 0"/>
    <parent link="link_right_index_proximal"/>
    <child link="link_right_index_intermediate"/>
    <axis xyz="0 0 1"/>
    <limit lower="-0.1" upper="1.6" effort="49" velocity="999"/>
    <!-- <mimic joint="right_index_finger_proximal" multiplier="1.06399" offset="-0.04545"/> -->
  </joint>
  <link name="link_right_middle_proximal">
    <inertial>
      <origin xyz="0.001297 0.011934 -0.0060001" rpy="0 0 0"/>
      <mass value="0.0042403"/>
      <inertia ixx="6.6211e-07" ixy="-1.8461e-08" ixz="1.8002e-12" iyy="2.1167e-07" iyz="-6.6808e-12" izz="6.9397e-07"/>
    </inertial>
    <visual>
      <origin xyz="0 0 0" rpy="0 0 0"/>
      <geometry>
        <mesh filename="meshes/inspire_hand/visual/right_index_proximal.obj"/>
      </geometry>
    </visual>
    <collision>
      <origin xyz="0 0 0" rpy="0 0 0"/>
      <geometry>
        <mesh filename="meshes/inspire_hand/collision/right_index_proximal.obj"/>
      </geometry>
    </collision>
  </link>
  <joint name="right_middle_finger_proximal" type="revolute">
    <origin xyz="0.00611 -0.13706 -0.01295" rpy="-3.1416 0 0"/>
    <parent link="link_right_hand"/>
    <child link="link_right_middle_proximal"/>
    <axis xyz="0 0 1"/>
    <limit lower="-0.1" upper="1.6" effort="50" velocity="1000"/>
  </joint>
  <link name="link_right_middle_intermediate">
    <inertial>
      <origin xyz="0.001921 0.020796 -0.005" rpy="0 0 0"/>
      <mass value="0.0050396"/>
      <inertia ixx="9.5822e-07" ixy="1.1425e-07" ixz="-2.4791e-12" iyy="1.0646e-07" iyz="5.9173e-12" izz="9.8384e-07"/>
    </inertial>
    <visual>
      <origin xyz="0 0 0" rpy="0 0 0"/>
      <geometry>
        <mesh filename="meshes/inspire_hand/visual/right_middle_intermediate.obj"/>
      </geometry>
    </visual>
    <collision>
      <origin xyz="0 0 0" rpy="0 0 0"/>
      <geometry>
        <mesh filename="meshes/inspire_hand/collision/right_middle_intermediate.obj"/>
      </geometry>
    </collision>
  </link>
  <joint name="mimic_right_middle_intermediate" type="revolute">
    <origin xyz="-0.0024229 0.032041 -0.001" rpy="0 0 0"/>
    <parent link="link_right_middle_proximal"/>
    <child link="link_right_middle_intermediate"/>
    <axis xyz="0 0 1"/>
    <limit lower="-0.1" upper="1.6" effort="49" velocity="999"/>
    <!-- <mimic joint="right_middle_finger_proximal" multiplier="1.06399" offset="-0.04545"/> -->
  </joint>
  <link name="link_right_ring_proximal">
    <inertial>
      <origin xyz="0.001297 0.011934 -0.0060002" rpy="0 0 0"/>
      <mass value="0.0042403"/>
      <inertia ixx="6.6211e-07" ixy="-1.8461e-08" ixz="1.5793e-12" iyy="2.1167e-07" iyz="-6.6868e-12" izz="6.9397e-07"/>
    </inertial>
    <visual>
      <origin xyz="0 0 0" rpy="0 0 0"/>
      <geometry>
        <mesh filename="meshes/inspire_hand/visual/right_index_proximal.obj"/>
      </geometry>
    </visual>
    <collision>
      <origin xyz="0 0 0" rpy="0 0 0"/>
      <geometry>
        <mesh filename="meshes/inspire_hand/collision/right_index_proximal.obj"/>
      </geometry>
    </collision>
  </link>
  <joint name="right_ring_finger_proximal" type="revolute">
    <origin xyz="0.00611 -0.13691 0.0062872" rpy="3.0892 0 0"/>
    <parent link="link_right_hand"/>
    <child link="link_right_ring_proximal"/>
    <axis xyz="0 0 1"/>
    <limit lower="-0.1" upper="1.6" effort="50" velocity="1000"/>
  </joint>
  <link name="link_right_ring_intermediate">
    <inertial>
      <origin xyz="0.0021753 0.019567 -0.005" rpy="0 0 0"/>
      <mass value="0.0045683"/>
      <inertia ixx="7.6286e-07" ixy="8.0635e-08" ixz="-6.1562e-13" iyy="9.431e-08" iyz="5.8619e-13" izz="7.8177e-07"/>
    </inertial>
    <visual>
      <origin xyz="0 0 0" rpy="0 0 0"/>
      <geometry>
        <mesh filename="meshes/inspire_hand/visual/right_index_intermediate.obj"/>
      </geometry>
    </visual>
    <collision>
      <origin xyz="0 0 0" rpy="0 0 0"/>
      <geometry>
        <mesh filename="meshes/inspire_hand/collision/right_index_intermediate.obj"/>
      </geometry>
    </collision>
  </link>
  <joint name="mimic_right_ring_intermediate" type="revolute">
    <origin xyz="-0.0024229 0.032041 -0.001" rpy="0 0 0"/>
    <parent link="link_right_ring_proximal"/>
    <child link="link_right_ring_intermediate"/>
    <axis xyz="0 0 1"/>
    <limit lower="-0.1" upper="1.6" effort="49" velocity="999"/>
    <!-- <mimic joint="right_ring_finger_proximal" multiplier="1.06399" offset="-0.04545"/> -->
  </joint>
  <link name="link_right_pinky_proximal">
    <inertial>
      <origin xyz="0.001297 0.011934 -0.0060001" rpy="0 0 0"/>
      <mass value="0.0042403"/>
      <inertia ixx="6.6211e-07" ixy="-1.8461e-08" ixz="1.6907e-12" iyy="2.1167e-07" iyz="-6.9334e-12" izz="6.9397e-07"/>
    </inertial>
    <visual>
      <origin xyz="0 0 0" rpy="0 0 0"/>
      <geometry>
        <mesh filename="meshes/inspire_hand/visual/right_index_proximal.obj"/>
      </geometry>
    </visual>
    <collision>
      <origin xyz="0 0 0" rpy="0 0 0"/>
      <geometry>
        <mesh filename="meshes/inspire_hand/collision/right_index_proximal.obj"/>
      </geometry>
    </collision>
  </link>
  <joint name="right_pinky_finger_proximal" type="revolute">
    <origin xyz="0.00611 -0.13571 0.025488" rpy="3.0369 0 0"/>
    <parent link="link_right_hand"/>
    <child link="link_right_pinky_proximal"/>
    <axis xyz="0 0 1"/>
    <limit lower="-0.1" upper="1.6" effort="50" velocity="1000"/>
  </joint>
  <link name="link_right_pinky_intermediate">
    <inertial>
      <origin xyz="0.0024748 0.016203 -0.0050031" rpy="0 0 0"/>
      <mass value="0.0035996"/>
      <inertia ixx="4.3913e-07" ixy="4.1418e-08" ixz="3.7168e-11" iyy="7.0247e-08" iyz="5.8613e-11" izz="4.4867e-07"/>
    </inertial>
    <visual>
      <origin xyz="0 0 0" rpy="0 0 0"/>
      <geometry>
        <mesh filename="meshes/inspire_hand/visual/right_pinky_intermediate.obj"/>
      </geometry>
    </visual>
    <collision>
      <origin xyz="0 0 0" rpy="0 0 0"/>
      <geometry>
        <mesh filename="meshes/inspire_hand/collision/right_pinky_intermediate.obj"/>
      </geometry>
    </collision>
  </link>
  <joint name="mimic_right_pinky_intermediate" type="revolute">
    <origin xyz="-0.0024229 0.032041 -0.001" rpy="0 0 0"/>
    <parent link="link_right_pinky_proximal"/>
    <child link="link_right_pinky_intermediate"/>
    <axis xyz="0 0 1"/>
    <limit lower="-0.1" upper="1.6" effort="49" velocity="999"/>
    <!-- <mimic joint="right_pinky_finger_proximal" multiplier="1.06399" offset="-0.04545"/> -->
  </joint>
  <link name="link_right_hip_x">
    <inertial>
      <inertia ixx="0.00001" ixy="0.00000" ixz="0.00000" iyy="0.00001" iyz="0.00000" izz="0.00001"/>
      <origin rpy="0.00000 0.00000 0.00000" xyz="0.00000 0.00000 0.00000"/>
      <mass value="4.08300"/>
    </inertial>
    <visual name="visual_right_hip_x">
      <origin rpy="3.14159 -0.00000 1.57080" xyz="0.00000 0.11860 0.09568"/>
      <material name="Material__26_006"/>
      <geometry>
        <mesh filename="./meshes/obj/visual_right_hip_x.obj" scale="0.01000 0.01000 0.01000"/>
      </geometry>
    </visual>
  </link>
  <link name="link_right_hip_z">
    <inertial>
      <inertia ixx="0.00001" ixy="0.00000" ixz="0.00000" iyy="0.00001" iyz="0.00000" izz="0.00001"/>
      <origin rpy="0.00000 0.00000 0.00000" xyz="0.00000 0.00000 0.00000"/>
      <mass value="0.54900"/>
    </inertial>
    <visual name="visual_right_hip_z">
      <origin rpy="3.14159 -0.26180 1.57080" xyz="0.00000 0.08979 0.05512"/>
      <material name="Material__26_007"/>
      <geometry>
        <mesh filename="./meshes/obj/visual_right_hip_z.obj" scale="0.01000 0.01000 0.01000"/>
      </geometry>
    </visual>
  </link>
  <link name="link_right_lower_arm">
    <inertial>
      <inertia ixx="0.00250" ixy="-0.00000" ixz="0.00000" iyy="0.00500" iyz="0.00000" izz="0.00500"/>
      <origin rpy="0.00000 0.00000 0.00000" xyz="-0.00034 0.00006 -0.08079"/>
      <mass value="1.36400"/>
    </inertial>
    <visual name="visual_right_lower_arm">
      <origin rpy="3.14159 -0.00000 1.39626" xyz="0.03863 0.22422 -0.12143"/>
      <material name="Material__25_011"/>
      <geometry>
        <mesh filename="./meshes/obj/visual_right_lower_arm.obj" scale="0.01000 0.01000 0.01000"/>
      </geometry>
    </visual>
  </link>
  <link name="link_right_shin">
    <inertial>
      <inertia ixx="0.00375" ixy="0.00000" ixz="0.00000" iyy="0.04188" iyz="0.00000" izz="0.04188"/>
      <origin rpy="0.00000 0.00000 0.00000" xyz="0.05682 0.00000 -0.16645"/>
      <mass value="6.11700"/>
    </inertial>
    <visual name="visual_right_shin">
      <origin rpy="3.14159 -0.00000 1.57080" xyz="0.05662 0.11860 0.48901"/>
      <material name="Material__25_012"/>
      <geometry>
        <mesh filename="./meshes/obj/visual_right_shin.obj" scale="0.01000 0.01000 0.01000"/>
      </geometry>
    </visual>
  </link>
  <link name="link_right_shoulder_x">
    <inertial>
      <inertia ixx="0.00001" ixy="-0.00000" ixz="-0.00000" iyy="0.00001" iyz="0.00000" izz="0.00001"/>
      <origin rpy="0.00000 0.00000 0.00000" xyz="0.00045 0.00256 -0.09426"/>
      <mass value="3.62600"/>
    </inertial>
    <visual name="visual_right_shoulder_x">
      <origin rpy="3.14159 -0.00000 1.39626" xyz="0.03930 0.22605 -0.38982"/>
      <material name="Material__25_013"/>
      <geometry>
        <mesh filename="./meshes/obj/visual_right_shoulder_x.obj" scale="0.01000 0.01000 0.01000"/>
      </geometry>
    </visual>
  </link>
  <link name="link_right_shoulder_y">
    <inertial>
      <inertia ixx="0.00001" ixy="0.00000" ixz="-0.00000" iyy="0.00001" iyz="-0.00000" izz="0.00001"/>
      <origin rpy="0.00000 0.00000 0.00000" xyz="0.01702 -0.07075 -0.00114"/>
      <mass value="0.70000"/>
    </inertial>
    <visual name="visual_right_shoulder_y">
      <origin rpy="3.14159 0.34354 1.38531" xyz="0.02978 0.01179 -0.44511"/>
      <material name="Material__25_014"/>
      <geometry>
        <mesh filename="./meshes/obj/visual_right_shoulder_y.obj" scale="0.01000 0.01000 0.01000"/>
      </geometry>
    </visual>
  </link>
  <link name="link_right_thigh">
    <inertial>
      <inertia ixx="0.01440" ixy="0.00000" ixz="0.00000" iyy="0.11387" iyz="0.00000" izz="0.11387"/>
      <origin rpy="0.00000 0.00000 0.00000" xyz="-0.05411 0.00000 -0.12785"/>
      <mass value="8.28800"/>
    </inertial>
    <visual name="visual_right_thigh">
      <origin rpy="3.14159 -0.00000 1.57080" xyz="-0.05500 0.11860 0.16418"/>
      <material name="Material__25_015"/>
      <geometry>
        <mesh filename="./meshes/obj/visual_right_thigh.obj" scale="0.01000 0.01000 0.01000"/>
      </geometry>
    </visual>
  </link>
  <link name="link_right_upper_arm">
    <inertial>
      <inertia ixx="0.00939" ixy="-0.00002" ixz="-0.00161" iyy="0.02159" iyz="-0.00000" izz="0.02138"/>
      <origin rpy="0.00000 0.00000 0.00000" xyz="0.00033 -0.00121 -0.05307"/>
      <mass value="1.59700"/>
    </inertial>
    <visual name="visual_right_upper_arm">
      <origin rpy="-3.07499 0.00000 1.39626" xyz="0.02978 0.22738 -0.20506"/>
      <material name="Material__25_016"/>
      <geometry>
        <mesh filename="./meshes/obj/visual_right_upper_arm.obj" scale="0.01000 0.01000 0.01000"/>
      </geometry>
    </visual>
  </link>
  <link name="link_right_wrist_x">
    <inertial>
      <inertia ixx="0.00001" ixy="0.00000" ixz="-0.00000" iyy="0.00001" iyz="-0.00000" izz="0.00001"/>
      <origin rpy="0.00000 0.00000 0.00000" xyz="-0.00000 0.00000 0.00000"/>
      <mass value="0.00700"/>
    </inertial>
    <visual name="visual_right_wrist_x">
      <origin rpy="3.14159 -0.00000 1.39626" xyz="0.03599 0.23813 0.11114"/>
      <material name="Material__26_008"/>
      <geometry>
        <mesh filename="./meshes/obj/visual_right_wrist_x.obj" scale="0.01000 0.01000 0.01000"/>
      </geometry>
    </visual>
  </link>
  <link name="link_right_wrist_z">
    <inertial>
      <inertia ixx="0.00252" ixy="-0.00000" ixz="-0.00024" iyy="0.00500" iyz="-0.00000" izz="0.00498"/>
      <origin rpy="0.00000 0.00000 0.00000" xyz="-0.00889 0.00157 -0.04962"/>
      <mass value="1.10000"/>
    </inertial>
    <visual name="visual_right_wrist_z">
      <origin rpy="-3.09281 0.00000 1.39626" xyz="0.03226 0.22549 -0.00479"/>
      <material name="Material__25_017"/>
      <geometry>
        <mesh filename="./meshes/obj/visual_right_wrist_z.obj" scale="0.01000 0.01000 0.01000"/>
      </geometry>
    </visual>
  </link>
  <link name="link_torso_x">
    <inertial>
      <inertia ixx="0.00001" ixy="0.00000" ixz="0.00000" iyy="0.00001" iyz="0.00000" izz="0.00001"/>
      <origin rpy="0.00000 0.00000 0.00000" xyz="-0.03457 0.00000 0.00000"/>
      <mass value="0.16300"/>
    </inertial>
    <visual name="visual_torso_x">
      <origin rpy="3.14159 -0.00000 1.57080" xyz="0.00000 0.00000 -0.10528"/>
      <material name="Material__26_009"/>
      <geometry>
        <mesh filename="./meshes/obj/visual_torso_x.obj" scale="0.01000 0.01000 0.01000"/>
      </geometry>
    </visual>
  </link>
  <link name="link_torso_y">
    <inertial>
      <inertia ixx="0.05333" ixy="0.00000" ixz="0.00000" iyy="0.03333" iyz="0.00000" izz="0.03333"/>
      <origin rpy="0.00000 0.00000 0.00000" xyz="0.07197 0.00000 0.22498"/>
      <mass value="16.74800"/>
    </inertial>
    <visual name="visual_torso_y">
      <origin rpy="3.14159 -0.00000 1.57080" xyz="0.08635 0.00000 -0.10430"/>
      <material name="Material__29"/>
      <geometry>
        <mesh filename="./meshes/obj/visual_torso_y.obj" scale="0.01000 0.01000 0.01000"/>
      </geometry>
    </visual>
  </link>
  <link name="link_torso_z">
    <inertial>
      <inertia ixx="0.00001" ixy="0.00000" ixz="0.00000" iyy="0.00001" iyz="0.00000" izz="0.00001"/>
      <origin rpy="0.00000 0.00000 0.00000" xyz="0.00000 0.00000 0.07652"/>
      <mass value="2.08700"/>
    </inertial>
    <visual name="visual_torso_z">
      <origin rpy="3.14159 -0.00000 1.57080" xyz="0.00000 0.00000 0.00000"/>
      <material name="Material__26_010"/>
      <geometry>
        <mesh filename="./meshes/obj/visual_torso_z.obj" scale="0.01000 0.01000 0.01000"/>
      </geometry>
    </visual>
  </link>
  <material name="Material__25_001">
    <color rgba="0.91373 0.91373 0.91373 1.00000"/>
  </material>
  <material name="Material__25_002">
    <color rgba="0.91373 0.91373 0.91373 1.00000"/>
  </material>
  <material name="Material__25_003">
    <color rgba="0.91373 0.91373 0.91373 1.00000"/>
  </material>
  <material name="Material__25_004">
    <color rgba="0.91373 0.91373 0.91373 1.00000"/>
  </material>
  <material name="Material__25_005">
    <color rgba="0.91373 0.91373 0.91373 1.00000"/>
  </material>
  <material name="Material__25_006">
    <color rgba="0.91373 0.91373 0.91373 1.00000"/>
  </material>
  <material name="Material__25_007">
    <color rgba="0.91373 0.91373 0.91373 1.00000"/>
  </material>
  <material name="Material__25_008">
    <color rgba="0.91373 0.91373 0.91373 1.00000"/>
  </material>
  <material name="Material__25_009">
    <color rgba="0.91373 0.91373 0.91373 1.00000"/>
  </material>
  <material name="Material__25_010">
    <color rgba="0.91373 0.91373 0.91373 1.00000"/>
  </material>
  <material name="Material__25_011">
    <color rgba="0.91373 0.91373 0.91373 1.00000"/>
  </material>
  <material name="Material__25_012">
    <color rgba="0.91373 0.91373 0.91373 1.00000"/>
  </material>
  <material name="Material__25_013">
    <color rgba="0.91373 0.91373 0.91373 1.00000"/>
  </material>
  <material name="Material__25_014">
    <color rgba="0.91373 0.91373 0.91373 1.00000"/>
  </material>
  <material name="Material__25_015">
    <color rgba="0.91373 0.91373 0.91373 1.00000"/>
  </material>
  <material name="Material__25_016">
    <color rgba="0.91373 0.91373 0.91373 1.00000"/>
  </material>
  <material name="Material__25_017">
    <color rgba="0.91373 0.91373 0.91373 1.00000"/>
  </material>
  <material name="Material__26">
    <color rgba="0.01961 0.01961 0.01961 1.00000"/>
  </material>
  <material name="Material__26_001">
    <color rgba="0.01961 0.01961 0.01961 1.00000"/>
  </material>
  <material name="Material__26_002">
    <color rgba="0.01961 0.01961 0.01961 1.00000"/>
  </material>
  <material name="Material__26_003">
    <color rgba="0.01961 0.01961 0.01961 1.00000"/>
  </material>
  <material name="Material__26_004">
    <color rgba="0.01961 0.01961 0.01961 1.00000"/>
  </material>
  <material name="Material__26_005">
    <color rgba="0.01961 0.01961 0.01961 1.00000"/>
  </material>
  <material name="Material__26_006">
    <color rgba="0.01961 0.01961 0.01961 1.00000"/>
  </material>
  <material name="Material__26_007">
    <color rgba="0.01961 0.01961 0.01961 1.00000"/>
  </material>
  <material name="Material__26_008">
    <color rgba="0.01961 0.01961 0.01961 1.00000"/>
  </material>
  <material name="Material__26_009">
    <color rgba="0.01961 0.01961 0.01961 1.00000"/>
  </material>
  <material name="Material__26_010">
    <color rgba="0.01961 0.01961 0.01961 1.00000"/>
  </material>
  <material name="Material__29">
    <texture filename="./meshes/obj/maps/2.jpg"/>
    <color rgba="0.49804 0.49804 0.49804 1.00000"/>
  </material>
</robot>